<?xml version="1.0" ?>
<!-- =================================================================================== -->
<!-- |    This document was autogenerated by xacro from gripper_exportable.urdf.xacro  | -->
<!-- |    EDITING THIS FILE BY HAND IS NOT RECOMMENDED                                 | -->
<!-- =================================================================================== -->
<robot name="cob4-sdhx" xmlns:xacro="http://www.ros.org/wiki/xacro">
  <link name="base_link"/>
  <!-- joint between base_link and gripper_base_link -->
  <joint name="gripper_right_base_joint" type="fixed">
	<origin rpy="0 1.57079632679 0" xyz="0 0 0"/>
    <!--<origin rpy="-1.57079632679 -1.57079632679 -1.57079632679" xyz="0 0 0"/> -->
    <parent link="base_link"/>
    <child link="gripper_right_base_link"/>
  </joint>
  <link name="gripper_right_base_link">
    <inertial>
      <mass value="0.01"/>
      <origin xyz="0 0 0"/>
      <inertia ixx="0.001" ixy="0.0" ixz="0.0" iyy="0.001" iyz="0.0" izz="0.001"/>
    </inertial>
    <visual>
      <origin rpy="0 0 0" xyz="0 0 0"/>
      <geometry>
        <box size="0.001 0.001 0.001"/>
      </geometry>
    </visual>
    <collision>
      <origin rpy="0 0 0" xyz="0 0 0"/>
      <geometry>
        <box size="0.001 0.001 0.001"/>
      </geometry>
    </collision>
  </link>
  <!-- joint between base_link and gripper_palm_link -->
  <joint name="gripper_right_palm_joint" type="revolute">
    <origin rpy="0 0 0" xyz="0 0 0"/>
    <parent link="gripper_right_base_link"/>
    <child link="gripper_right_palm_link"/>
	<dynamics damping="0.0" friction="0.0"/>
	<axis xyz="0 0 1"/>
    <limit effort="200" lower="-3.141592654" upper="3.141592654" velocity="0.5"/>
  </joint>
  <link name="gripper_right_palm_link">
    <inertial>
      <mass value="0.4"/>
      <origin xyz="0 0 0"/>
      <inertia ixx="0.2" ixy="0.0" ixz="0.0" iyy="0.2" iyz="0.0" izz="0.2"/>
    </inertial>
    <visual>
      <origin rpy="0 0 0" xyz="0 0 0"/>
      <geometry>
        <mesh filename="package://cob_description/meshes/cob4_gripper/palm.stl"/>
      </geometry>
    </visual>
    <collision>
      <origin rpy="0 0 0" xyz="0 0 0"/>
      <geometry>
        <mesh filename="package://cob_description/meshes/cob4_gripper/palm.stl"/>
      </geometry>
    </collision>
  </link>
  <joint name="gripper_right_grasp_joint" type="fixed">
    <origin rpy="0 -1.57079632679 0" xyz="0 0 0.11"/>
    <parent link="gripper_right_base_link"/>
    <child link="gripper_right_grasp_link"/>
  </joint>
  <link name="gripper_right_grasp_link">
    <inertial>
      <mass value="0.01"/>
      <origin xyz="0 0 0"/>
      <inertia ixx="0.001" ixy="0.0" ixz="0.0" iyy="0.001" iyz="0.0" izz="0.001"/>
    </inertial>
    <visual>
      <origin rpy="0 0 0" xyz="0 0 0"/>
      <geometry>
        <box size="0.001 0.001 0.001"/>
      </geometry>
    </visual>
    <collision>
      <origin rpy="0 0 0" xyz="0 0 0"/>
      <geometry>
        <box size="0.001 0.001 0.001"/>
      </geometry>
    </collision>
  </link>
  <!-- joint between base_link and gripper_base_link -->
  <joint name="gripper_right_camera_joint" type="fixed">
    <origin rpy="0 1.57079632679 0" xyz="0 0 0"/>
    <parent link="gripper_right_palm_link"/>
    <child link="gripper_right_camera_link"/>
  </joint>
  <link name="gripper_right_camera_link">
    <inertial>
      <mass value="0.01"/>
      <origin xyz="0 0 0"/>
      <inertia ixx="0.001" ixy="0.0" ixz="0.0" iyy="0.001" iyz="0.0" izz="0.001"/>
    </inertial>
    <visual>
      <origin rpy="0 0 0" xyz="0 0 0"/>
      <geometry>
        <box size="0.001 0.001 0.001"/>
      </geometry>
    </visual>
    <collision>
      <origin rpy="0 0 0" xyz="0 0 0"/>
      <geometry>
        <box size="0.001 0.001 0.001"/>
      </geometry>
    </collision>
  </link>
  <!-- joint between gripper_palm_link and gripper_finger_1_link -->
  <joint name="gripper_right_finger_1_joint" type="revolute">
    <origin rpy="0 0 -0.2" xyz="-0.04409 0.02163  0"/>
    <parent link="gripper_right_camera_link"/>
    <child link="gripper_right_finger_1_link"/>
    <axis xyz="0 0 1"/>
    <dynamics damping="0.0" friction="0.0"/>
    <limit effort="200" lower="-1.047" upper="0.872" velocity="0.5"/>
  </joint>
  <link name="gripper_right_finger_1_link">
    <inertial>
      <mass value="0.1"/>
      <origin xyz="0 0 0"/>
      <inertia ixx="0.05" ixy="0.0" ixz="0.0" iyy="0.05" iyz="0.0" izz="0.05"/>
    </inertial>
    <visual>
      <origin rpy="0 0 0" xyz="0 0 0"/>
      <geometry>
        <mesh filename="package://cob_description/meshes/cob4_gripper/finger_1.stl"/>
      </geometry>
    </visual>
    <collision>
      <origin rpy="0 0 0" xyz="0 0 0"/>
      <geometry>
        <mesh filename="package://cob_description/meshes/cob4_gripper/finger_1.stl"/>
      </geometry>
    </collision>
  </link>
  <!-- joint between gripper_finger_1_link and gripper_finger_2_link -->
  <joint name="gripper_right_finger_2_joint" type="revolute">
    <origin rpy="0 0 0.3" xyz="-0.0712 0 0"/>
    <parent link="gripper_right_finger_1_link"/>
    <child link="gripper_right_finger_2_link"/>
    <axis xyz="0 0 1"/>
    <dynamics damping="0.0" friction="0.0"/>
    <limit effort="200" lower="-1.57079632679" upper="1.57079632679" velocity="0.5"/>
  </joint>
  <link name="gripper_right_finger_2_link">
    <inertial>
      <mass value="0.1"/>
      <origin xyz="0 0 0"/>
      <inertia ixx="0.05" ixy="0.0" ixz="0.0" iyy="0.05" iyz="0.0" izz="0.05"/>
    </inertial>
    <visual>
      <origin rpy="0 0 0" xyz="0 0 0"/>
      <geometry>
        <mesh filename="package://cob_description/meshes/cob4_gripper/finger_2.stl"/>
      </geometry>
    </visual>
    <collision>
      <origin rpy="0 0 0" xyz="0 0 0"/>
      <geometry>
        <mesh filename="package://cob_description/meshes/cob4_gripper/finger_2.stl"/>
      </geometry>
    </collision>
  </link>

  <klampt package_root="/opt/ros/kinetic/share" flip_yz="1" use_vis_geom="1" />

</robot>

